Workbook

Sheet Trang bia
D1: TẬP ĐOÀN CÔNG NGHIỆP - VIỄN THÔNG QUÂN ĐỘI
D2: TỔNG CÔNG TY GIẢI PHÁP DOANH NGHIỆP VIETTEL
A7: <TÊN DỰ ÁN/TÀI LIỆU ULNL>
C11: Mã dự án/ mã yêu cầu:
C12: Mã tài liệu: | E12: <Mã tài liệu>
C13: Lần ước lượng | E13: Ef
A16: Người lập:
C17: <Tên người lập> | F17: <Ngày lập>
C18: <Chức vụ>
A22: Người kiểm tra:
C23: <Tên người kiểm tra> | F23: <Ngày kiểm tra>
C24: <Chức vụ>
A28: Người phê duyệt:
C29: <Tên người phê duyệt> | F29: <Ngày phê duyệt>
C30: <Chức vụ>

Sheet Tong hop
A1: ="PHỤ LỤC 02: ƯỚC LƯỢNG NỖ LỰC CHI TIẾT "&'Trang bia'!A7&CHAR(10)&"(Đính kèm theo báo cáo số........./BC-........., ngày tháng năm... về tài liệu ước lượng nỗ lực chi tiết)"
A2: BẢNG TÍNH TOÁN NỖ LỰC THỰC HIỆN DỰ ÁN
A3: I - Tổng nỗ lực thực hiện yêu cầu theo hướng dẫn
B5: Nguồn lực cho các công việc trong dự án
B6: STT | C6: Công việc | D6: Diễn giải | E6: Nỗ lực chưa tái sử dụng (MD) | F6: Nỗ lực sau khi tái sử dụng (MD)
B7: 1 | C7: Tổng nỗ lực chức năng | D7: Tổng nỗ lực thực hiện cho chức năng bao gồm giải pháp phát triển kiểm thử | E7: ='NL Chuc nang'!N50/8+'NL Chuc nang'!N49/8 | F7: =ROUNDUP('NL Chuc nang'!E50/8+'NL Chuc nang'!E49/8,2) | G7: =IFERROR((E7-F7)/E7,0)
B8: 2 | C8: Giải pháp | D8: Tổng nỗ lực thực hiện giải pháp | E8: ='NL Chuc nang'!K50/8 | F8: =ROUNDUP('NL Chuc nang'!F50/8,2)
B9: 3 | C9: Phát triển | D9: Tổng nỗ lực thực hiện phát triển | E9: =ROUND('NL Chuc nang'!L50/8,2) | F9: ='NL Chuc nang'!G50/8
C10: Unit test | D10: Tổng nỗ lực thực hiện unit test | E10: =ROUNDDOWN('NL Chuc nang'!L49/8,2) | F10: =ROUND('NL Chuc nang'!G49/8,2)
B11: 4 | C11: Kiểm thử | D11: Tổng nỗ lực thực hiện kiểm thử | E11: ='NL Chuc nang'!M50/8 | F11: =ROUNDDOWN('NL Chuc nang'!H50/8,2)
B12: 5 | C12: Nỗ lực thực hiện phi chức năng | D12: Tổng nỗ lực thực hiện các công việc phi chức năng | E12: =ROUND('NL Phi CN'!E57/8,2) | F12: =ROUNDUP('NL Phi CN'!E57/8,2)
B13: 6 | C13: Nỗ lực thực hiện tiêu chuẩn QTDL | D13: Tổng nỗ lực thực hiện cho tiêu chuẩn QTDL (nếu có sheet NL QTDL thì cập nhật tham chiếu) | E13: 0 | F13: 0
B14: 7 | C14: Tổng nỗ lực thực hiện (MD) | D14: =(1) + (5) + (6) | E14: =ROUND(E12+E7+E13,2) | F14: =F12+F7+F13
A16: II - Tổng nỗ lực phân bổ thuê ngoài và tự thực hiện
B18: STT | C18: Công việc | D18: Diễn giải | E18: Tổng nỗ lực (bao gồm thuê ngoài và tự thực hiện) | F18: Nỗ lực thuê ngoài | G18: Nỗ lực tự thực hiện | H18: Tỉ lệ nỗ lực từng công việc (%) | I18: Tỉ lệ thuê ngoài (%) | J18: Tỉ lệ tự thực hiện (%)
B19: 1 | C19: Giải pháp | D19: Tổng nỗ lực thực hiện giải pháp | E19: =F19+G19 | F19: =ROUND('NL Chuc nang'!W50/8,2) | G19: =ROUND('NL Chuc nang'!Z50/8,2) | H19: =IFERROR(ROUNDUP(E19/$E$25,2),0) | I19: =IFERROR(F19/E19,0) | J19: =IFERROR(G19/E19,0)
B20: 2 | C20: Phát triển | D20: Tổng nỗ lực thực hiện phát triển | E20: =F20+G20 | F20: =ROUND('NL Chuc nang'!X50/8,2) | G20: ='NL Chuc nang'!AA50/8 | H20: =IFERROR(E20/$E$25,0) | I20: =IFERROR(F20/E20,0) | J20: =IFERROR(G20/E20,0)
B21: 3 | C21: Unit test | D21: Tổng nỗ lực thực hiện unit test | E21: =F21+G21 | F21: =ROUND('NL Chuc nang'!X49/8,2) | G21: =ROUND('NL Chuc nang'!AA49/8,2) | H21: =IFERROR(E21/$E$25,0) | I21: =IFERROR(F21/E21,0) | J21: =IFERROR(G21/E21,0)
B22: 4 | C22: Kiểm thử | D22: Tổng nỗ lực thực hiện kiểm thử | E22: =F22+G22 | F22: =ROUNDDOWN('NL Chuc nang'!Y50/8,2) | G22: =ROUNDUP('NL Chuc nang'!AB50/8,2) | H22: =IFERROR(ROUNDDOWN(E22/$E$25,2),0) | I22: =IFERROR(F22/E22,0) | J22: =IFERROR(G22/E22,0)
B23: 5 | C23: Phi chức năng | D23: Tổng nỗ lực thực hiện các công việc phi chức năng | E23: =F23+G23 | F23: ='NL Phi CN'!G57/8 | G23: =ROUND('NL Phi CN'!H57/8,2) | H23: =IFERROR(ROUND(E23/$E$25,2),0) | I23: =IFERROR(F23/E23,0) | J23: =IFERROR(G23/E23,0)
B24: 6 | C24: Nỗ lực thực hiện tiêu chuẩn QTDL | D24: Tổng nỗ lực thực hiện cho tiêu chuẩn QTDL | E24: =F24+G24 | F24: 0 | G24: 0 | H24: =IFERROR(E24/$E$25,0) | I24: =IFERROR(F24/E24,0) | J24: =IFERROR(G24/E24,0)
B25: 7 | C25: Tổng nỗ lực thực hiện (MD) | D25: = (1) + (2) + (3) + (4) + (5) + (6) | E25: =F25+G25 | F25: =SUM(F19:F24) | G25: =SUM(G19:G24) | H25: =IFERROR(E25/$E$25,0) | I25: =IFERROR(F25/E25,0) | J25: =IFERROR(G25/E25,0)
B26: 8 | C26: Tổng nỗ lực thực hiện (MM) | D26: Thuê ngoài: 1 MM = 22 MDs Nội bộ: 1 MM = 22 MDs | E26: =ROUNDUP(SUM(F26:G26),2) | F26: =F25/22 | G26: =G25/22 | H26: =IFERROR(E26/$E$25,0) | I26: =IFERROR(F26/E26,0) | J26: =IFERROR(G26/E26,0)

Sheet NL Chuc nang
A1: ='Trang bia'!A7
A2: BẢNG DANH SÁCH CHỨC NĂNG
A3: * Điền thông tin vào các cột màu trắng
A4: Giải pháp bao gồm Phân tích thiết kế; Phát triển: gồm lập trình, sửa lỗi, unit test; Kiểm thử: Kịch bản kiểm thử, Test tính năng, hướng dẫn sử dụng
A6: TT | B6: Mã yêu cầu | C6: Tên Chức năng | D6: Mô tả chức năng | E6: Nỗ lực thực hiện sau khi tái sử dụng (MH) | I6: Mã chức năng | J6: Tên loại chức năng | K6: Nỗ lực thực hiện chưa tái sử dụng | O6: Tỷ lệ tái sử dụng (%) | R6: Tái sử dụng từ chức năng/hệ thống nào | S6: Ghi chú | T6: Có thuê ngoài thực hiện không? | W6: Nỗ lực thuê ngoài (MH) | Z6: Nỗ lực tự thực hiện (MH)
E7: Tổng nỗ lực thực hiện (MH) | F7: Giải pháp | G7: Phát triển | H7: Kiểm thử | K7: Giải pháp | L7: Phát triển | M7: Kiểm thử | N7: Tổng nỗ lực (MH) | O7: Giải pháp | P7: Phát triển | Q7: Kiểm thử | T7: Giải pháp | U7: Phát triển | V7: Kiểm thử | W7: Giải pháp | X7: Phát triển | Y7: Kiểm thử | Z7: Giải pháp | AA7: Phát triển | AB7: Kiểm thử
A8: A | B8: NỖ LỰC CHỨC NĂNG
A9: I | B9: Nhóm 1

Sheet NL Phi CN
A1: ='Trang bia'!A7
A2: ƯỚC LƯỢNG NỖ LỰC DỰ ÁN - PHI CHỨC NĂNG, CÔNG VIỆC KHÁC
A3: * Điền thông tin vào các cột màu trắng
C4: Người thực hiện:
C5: Ngày thực hiện:
C6: Tổng nỗ lực (MH): | D6: =E57
C7: Tổng nỗ lực (MM): | D7: =D6/8/22
A8: TT | B8: Mã đầu việc | C8: Tên đầu việc | D8: Mô tả | E8: Tổng nỗ lực thực hiện (manhours) | F8: Có thuê ngoài thực hiện không? | G8: Nỗ lực thuê ngoài | H8: Nỗ lực tự thực hiện
B10: I | C10: Nỗ lực trước triển khai
A11: 1 | B11: QTDA | C11: Quản trị dự án | D11: Nỗ lực QTDA (QTDA, thẩm định, test, nghiệm thu) = 10% tổng nỗ lực dự án | E11: ='NL Chuc nang'!E48*0.1 | F11: Không | G11: =IF(F11="Có",E11,0) | H11: =IF(E11="",0,E11-G11)
A12: 5 | B12: RV1 | C12: Review tài liệu giải pháp | D12: Review TKTT 2 lần (QTDA, TPGP, TPPT, KT, BA) | E12: =IF(B12="","",VLOOKUP(B12,'CSDL Phi CN'!$B$3:$H$72,6,FALSE()))*5*2 | F12: Không | G12: =IF(F12="Có",E12,0) | H12: =IF(E12="",0,E12-G12)
A13: 6 | B13: RV1 | D13: Review PTYC, Prototype 2 lần × 6 module | E13: =IF(B13="","",VLOOKUP(B13,'CSDL Phi CN'!$B$3:$H$72,6,FALSE()))*6*2 | F13: Không | G13: =IF(F13="Có",E13,0) | H13: =IF(E13="",0,E13-G13)
A14: 7 | B14: RV1 | D14: Review TKCT 2 lần × 6 module | E14: =IF(B14="","",VLOOKUP(B14,'CSDL Phi CN'!$B$3:$H$72,6,FALSE()))*6*2 | F14: Không | G14: =IF(F14="Có",E14,0) | H14: =IF(E14="",0,E14-G14)
A15: 8 | B15: RV1 | D15: Review TKCSDL 2 lần × 6 module | E15: =IF(B15="","",VLOOKUP(B15,'CSDL Phi CN'!$B$3:$H$72,6,FALSE()))*6*2 | F15: Không | G15: =IF(F15="Có",E15,0) | H15: =IF(E15="",0,E15-G15)
A16: 9 | B16: RV1 | D16: Review KBKTL 2 lần × 6 module | E16: =IF(B16="","",VLOOKUP(B16,'CSDL Phi CN'!$B$3:$H$72,6,FALSE()))*6*2 | F16: Không | G16: =IF(F16="Có",E16,0) | H16: =IF(E16="",0,E16-G16)
A17: 10 | B17: RV1 | D17: Review HDSD × 6 module | E17: =IF(B17="","",VLOOKUP(B17,'CSDL Phi CN'!$B$3:$H$72,6,FALSE()))*6 | F17: Không | G17: =IF(F17="Có",E17,0) | H17: =IF(E17="",0,E17-G17)
A18: 11 | B18: NT1 | C18: Nghiệm thu | D18: Nghiệm thu nội bộ 6 Module | E18: =IF(B18="","",VLOOKUP(B18,'CSDL Phi CN'!$B$3:$H$72,6,FALSE()))*6 | F18: Không | G18: =IF(F18="Có",E18,0) | H18: =IF(E18="",0,E18-G18)
A19: 12 | B19: NT2 | D19: Nghiệm thu KH 6 module × 3 người | E19: =IF(B19="","",VLOOKUP(B19,'CSDL Phi CN'!$B$3:$H$72,6,FALSE()))*6*3 | F19: Không | G19: =IF(F19="Có",E19,0) | H19: =IF(E19="",0,E19-G19)
A20: 13 | B20: UC3 | C20: Merge code | D20: Merge code 10 lần trong phát triển | E20: =IF(B20="","",VLOOKUP(B20,'CSDL Phi CN'!$B$3:$H$72,6,FALSE()))*10 | F20: Không | G20: =IF(F20="Có",E20,0) | H20: =IF(E20="",0,E20-G20)
A21: 14 | B21: UC4 | C21: Test merge code | D21: Test merge code 10 lần | E21: =IF(B21="","",VLOOKUP(B21,'CSDL Phi CN'!$B$3:$H$72,6,FALSE()))*10 | F21: Không | G21: =IF(F21="Có",E21,0) | H21: =IF(E21="",0,E21-G21)
A22: 15 | B22: RV2 | C22: Review code | D22: Review code 6 module × 2 lần | E22: =IF(B22="","",VLOOKUP(B22,'CSDL Phi CN'!$B$3:$H$72,6,FALSE()))*6*2 | F22: Không | G22: =IF(F22="Có",E22,0) | H22: =IF(E22="",0,E22-G22)
A23: 16 | B23: VH1 | C23: Rà soát ATTT server | D23: Rà soát ATTT server 1 lần upcode triển khai | E23: =IF(B23="","",VLOOKUP(B23,'CSDL Phi CN'!$B$3:$H$72,6,FALSE())) | F23: Không | G23: =IF(F23="Có",E23,0) | H23: =IF(E23="",0,E23-G23)
A24: 17 | B24: VH2 | C24: Rà soát ATTT ứng dụng | D24: Rà soát ATTT ứng dụng 1 lần upcode triển khai | E24: =IF(B24="","",VLOOKUP(B24,'CSDL Phi CN'!$B$3:$H$72,6,FALSE())) | F24: Không | G24: =IF(F24="Có",E24,0) | H24: =IF(E24="",0,E24-G24)
A25: 18 | B25: UC2 | C25: Review và phê duyệt WO upcode | D25: Review và phê duyệt WO upcode 1 lần | E25: =IF(B25="","",VLOOKUP(B25,'CSDL Phi CN'!$B$3:$H$72,6,FALSE())) | F25: Không | G25: =IF(F25="Có",E25,0) | H25: =IF(E25="",0,E25-G25)
A26: 19 | B26: UC5 | C26: Tham gia upcode | D26: Tham gia upcode 1 lần × 3 người (web, service, test) | E26: =IF(B26="","",VLOOKUP(B26,'CSDL Phi CN'!$B$3:$H$72,6,FALSE()))*3 | F26: Không | G26: =IF(F26="Có",E26,0) | H26: =IF(E26="",0,E26-G26)
A27: 20 | B27: UC6 | C27: Release phiên bản | D27: Release jenkins + IBM 1 lần trong phát triển | E27: =IF(B27="","",VLOOKUP(B27,'CSDL Phi CN'!$B$3:$H$72,6,FALSE())) | F27: Không | G27: =IF(F27="Có",E27,0) | H27: =IF(E27="",0,E27-G27)
A28: 21 | B28: TK5 | C28: Triển khai hệ thống mới trên hạ tầng mới | D28: Triển khai hệ thống mới | E28: =IF(B28="","",VLOOKUP(B28,'CSDL Phi CN'!$B$3:$H$72,6,FALSE())) | F28: Không | G28: =IF(F28="Có",E28,0) | H28: =IF(E28="",0,E28-G28)
A29: 22 | B29: VH4 | C29: Khai báo cảnh báo giám sát | D29: Khai báo cảnh báo giám sát | E29: =IF(B29="","",VLOOKUP(B29,'CSDL Phi CN'!$B$3:$H$72,6,FALSE())) | F29: Không | G29: =IF(F29="Có",E29,0) | H29: =IF(E29="",0,E29-G29)
A30: 23 | B30: TK7 | C30: Hồ sơ kỹ thuật | D30: Hồ sơ kỹ thuật | E30: =IF(B30="","",VLOOKUP(B30,'CSDL Phi CN'!$B$3:$H$72,6,FALSE())) | F30: Không | G30: =IF(F30="Có",E30,0) | H30: =IF(E30="",0,E30-G30)
A31: 24 | B31: TK8 | C31: Bộ chỉ tiêu kỹ thuật | D31: Xây dựng và chuẩn hóa bộ chỉ tiêu kỹ thuật (×4) | E31: =IF(B31="","",VLOOKUP(B31,'CSDL Phi CN'!$B$3:$H$72,6,FALSE()))*4 | F31: Không | G31: =IF(F31="Có",E31,0) | H31: =IF(E31="",0,E31-G31)
A32: 25 | B32: SZ6 | C32: Sizing tự test đo trên lab | D32: Sizing >10 module | E32: =IF(B32="","",VLOOKUP(B32,'CSDL Phi CN'!$B$3:$H$72,6,FALSE())) | F32: Không | G32: =IF(F32="Có",E32,0) | H32: =IF(E32="",0,E32-G32)
A33: 26 | B33: SZ3 | C33: Sizing có hệ thống tham chiếu | D33: Sizing lại sau khi có hệ thống | E33: =IF(B33="","",VLOOKUP(B33,'CSDL Phi CN'!$B$3:$H$72,6,FALSE())) | F33: Không | G33: =IF(F33="Có",E33,0) | H33: =IF(E33="",0,E33-G33)
A34: 27 | B34: TK9 | C34: Dựng môi trường test hiệu năng | D34: Dựng môi trường test hiệu năng | E34: =IF(B34="","",VLOOKUP(B34,'CSDL Phi CN'!$B$3:$H$72,6,FALSE())) | F34: Không | G34: =IF(F34="Có",E34,0) | H34: =IF(E34="",0,E34-G34)
A35: 28 | B35: TK10 | C35: Test hiệu năng | D35: Test hiệu năng (×2) | E35: =IF(B35="","",VLOOKUP(B35,'CSDL Phi CN'!$B$3:$H$72,6,FALSE()))*2 | F35: Không | G35: =IF(F35="Có",E35,0) | H35: =IF(E35="",0,E35-G35)
A36: 29 | B36: TK11 | C36: Báo cáo và đánh giá hệ thống sau test hiệu năng | D36: Báo cáo, đánh giá sau test HN | E36: =IF(B36="","",VLOOKUP(B36,'CSDL Phi CN'!$B$3:$H$72,6,FALSE())) | F36: Không | G36: =IF(F36="Có",E36,0) | H36: =IF(E36="",0,E36-G36)
A37: 30 | B37: UC1 | C37: Làm các thủ tục upcode và bàn giao trên WO | D37: Thủ tục upcode + bàn giao 1 lần | E37: =IF(B37="","",VLOOKUP(B37,'CSDL Phi CN'!$B$3:$H$72,6,FALSE())) | F37: Không | G37: =IF(F37="Có",E37,0) | H37: =IF(E37="",0,E37-G37)
A38: 31 | B38: VH6 | C38: Hỗ trợ phản ánh GĐ1 | D38: Phản ánh GĐ1 mỗi tháng 12h × 12 tháng × 50.0% | E38: =288*0.5 | F38: Không | G38: =IF(F38="Có",E38,0) | H38: =IF(E38="",0,E38-G38)
A39: 32 | B39: TH | C39: Test Tích hợp hệ thống khác | D39: Test tích hợp với 2 hệ thống × 40h | E39: =40*2 | F39: Không | G39: =IF(F39="Có",E39,0) | H39: =IF(E39="",0,E39-G39)
A40: 33 | B40: DT6 | C40: Tài liệu hướng dẫn cài đặt | D40: TL HDCD cho 7 module × 2h | E40: =2*7 | F40: Không | G40: =IF(F40="Có",E40,0) | H40: =IF(E40="",0,E40-G40)
A41: 34 | C41: Hỗ trợ khách hàng đẩy dữ liệu lên hệ thống | D41: Hỗ trợ KH đẩy dữ liệu. Dự kiến 40h | E41: 40 | F41: Không | G41: =IF(F41="Có",E41,0) | H41: =IF(E41="",0,E41-G41)
...

Sheet Định nghĩa Loại Chức năng
A1: PHỤ LỤC 1.1 DANH SÁCH LOẠI CHỨC NĂNG
A3: STT | B3: Mã loại chức năng | C3: Tên loại chức năng | D3: Kỹ năng | E3: Mô tả (Trường thông tin hoặc bước xử lý nghiệp vụ) | F3: Ví dụ
A4: 1 | B4: NVJ1-PTM | C4: Xử lý nghiệp vụ đơn giản | D4: SERVICE - JAVA | E4: Nghiệp vụ nhỏ hơn 5 bước Bước là 1 xử lý logic được mô tả trong tài liệu giải pháp | F4: Tra cứu thông tin tài khoản Bankplus BCCS
A5: 2 | B5: NVJ2-PTM | C5: Xử lý nghiệp vụ trung bình | D5: SERVICE - JAVA | E5: Nghiệp vụ từ 5 - 10 bước | F5: Đấu nối di động
A6: 3 | B6: NVJ3-PTM | C6: Xử lý nghiệp vụ phức tạp | D6: SERVICE - JAVA | E6: Nghiệp vụ lớn hơn 10 bước | F6: Đấu nối cố định
A7: 4 | B7: CN_WEB_KT | C7: Chức năng giao diện kéo thả | D7: UI - WEB | E7: Bao gồm thông tin entity và màn hình Diagram tạo liên kết giữa các entity, xử lý validate và nghiệp vụ ở service
A8: 5 | B8: GD_WEB1 | C8: Chức năng giao diện web (chỉ có UI) | D8: UI - WEB | E8: Dưới 10 Component Component : là những hiển thị ra; case validate | F8: Tra cứu thông tin tài khoản Bankplus BCCS
A9: 6 | B9: GD_WEB2 | C9: Chức năng giao diện web 2 - Chỉ có UI | D9: UI - WEB | E9: Có 10-20 trường thông tin | F9: Giao diện đấu nối di động
A10: 7 | B10: GD_WEB3 | C10: Chức năng giao diện web 3 - chỉ có UI | D10: UI - WEB | E10: Có trên 20 trường thông tin | F10: Giao diện đấu nối cố định
A11: 8 | B11: BC1 | C11: Thiết kế báo cáo hàng cột đơn giản | D11: UI-Report | E11: Không sử dụng công thức trên hàng cột Số lượng trường xuất ra trên báo cáo nhỏ hơn 10 trường | F11: Là việc sử dụng công cụ Birt design để thiết kế báo cáo dạng hàng cột. Phần câu lệnh query để tạo dataset được ước lượng riêng.
A12: 9 | B12: BC2 | C12: Thiết kế báo cáo hàng cột trung bình | D12: UI-Report | E12: Có sử dụng công thức trên hàng cột Có số trường xuất ra từ 10 đến 20 trường
A13: 10 | B13: BC3 | C13: Thiết kế báo cáo hàng cột phức tạp | D13: UI-Report | E13: Số lượng trường xuất ra lớn hơn 20 trường
A14: 11 | B14: NVJ1-NC | C14: Xử lý nghiệp vụ đơn giản-nâng cấp | D14: SERVICE - JAVA | E14: Nghiệp vụ bổ sung nhỏ hơn 5 bước
A15: 12 | B15: NVJ2-NC | C15: Xử lý nghiệp vụ trung bình-nâng cấp | D15: SERVICE - JAVA | E15: Nghiệp vụ bổ sung từ 5 - 10 bước
A16: 13 | B16: NVJ3-NC | C16: Xử lý nghiệp vụ phức tạp - nâng cấp | D16: SERVICE - JAVA | E16: Nghiệp vụ lớn hơn 10 bước
A17: 14 | B17: DM1 | C17: Danh mục từ điển | D17: SERVICE - JAVA | E17: Danh mục không có tham chiếu
A18: 15 | B18: DM2 | C18: Danh mục có tham chiếu | D18: SERVICE - JAVA | E18: Danh mục có từ 1-3 tham chiếu
A19: 16 | B19: DM3 | C19: Danh mục có tham chiếu | D19: SERVICE - JAVA | E19: Danh mục có trên 3 tham chiếu
A20: 17 | B20: GD_MOBILE1 | C20: Giao diện - đơn giản | D20: UI - MOBILE | E20: < 5 trường thông tin
A21: 18 | B21: GD_MOBILE2 | C21: Giao diện - trung bình | D21: UI - MOBILE | E21: 5-10 trường thông tin
A22: 19 | B22: GD_MOBILE3 | C22: Giao diện - phức tạp | D22: UI - MOBILE | E22: > 10 trường thông tin
A23: 20 | B23: CN_MOBILE Client1 | C23: Chức năng Client- Đơn giản | D23: MOBILE | E23: < 5 trường thông tin - Component hiển thị thông tin: 1 đơn vị giao diện - Component nhập thông tin và xử lý thông tin: 2 đơn vị giao diện - Component phải gọi API riêng để lấy dữ liệu và xử lý dữ liệu: 3 đơn vị giao diện | F23: Trên giao diện của một chức năng có 1 Label, 2 textbox, 3 combobox (có gọi API để lấy dữ liệu) sẽ là: 1*1 + 2*2 + 3*3 = 12 trường thông tin
A24: 21 | B24: CN_MOBILE Client2 | C24: Chức năng Client- trung bình | D24: MOBILE | E24: 5-10 trường thông tin - Component hiển thị thông tin: 1 đơn vị giao diện - Component nhập thông tin và xử lý thông tin: 2 đơn vị giao diện - Component phải gọi API riêng để lấy dữ liệu và xử lý dữ liệu: 3 đơn vị giao diện | F24: Trên giao diện của một chức năng có 1 Label, 2 textbox, 3 combobox (có gọi API để lấy dữ liệu) sẽ là: 1*1 + 2*2 + 3*3 = 12 trường thông tin
A25: 22 | B25: CN_MOBILE Client1-NC | C25: Chức năng Client- Đơn giản | D25: MOBILE | E25: < 5 trường thông tin - Component hiển thị thông tin: 1 đơn vị giao diện - Component nhập thông tin và xử lý thông tin: 2 đơn vị giao diện - Component phải gọi API riêng để lấy dữ liệu và xử lý dữ liệu: 3 đơn vị giao diện | F25: Trên giao diện của một chức năng có 1 Label, 2 textbox, 3 combobox (có gọi API để lấy dữ liệu) sẽ là: 1*1 + 2*2 + 3*3 = 12 trường thông tin
A26: 23 | B26: CN_MOBILE Client2_NC | C26: Chức năng Client NC- trung bình | D26: MOBILE | E26: 5-10 trường thông tin - Component hiển thị thông tin: 1 đơn vị giao diện - Component nhập thông tin và xử lý thông tin: 2 đơn vị giao diện - Component phải gọi API riêng để lấy dữ liệu và xử lý dữ liệu: 3 đơn vị giao diện | F26: Trên giao diện của một chức năng có 1 Label, 2 textbox, 3 combobox (có gọi API để lấy dữ liệu) sẽ là: 1*1 + 2*2 + 3*3 = 12 trường thông tin
A27: 24 | B27: CN_MOBILE Client3-NC | C27: Chức năng Client- phức tạp | D27: MOBILE | E27: > 10 trường thông tin - Component hiển thị thông tin: 1 đơn vị giao diện - Component nhập thông tin và xử lý thông tin: 2 đơn vị giao diện - Component phải gọi API riêng để lấy dữ liệu và xử lý dữ liệu: 3 đơn vị giao diện | F27: Trên giao diện của một chức năng có 1 Label, 2 textbox, 3 combobox (có gọi API để lấy dữ liệu) sẽ là: 1*1 + 2*2 + 3*3 = 12 trường thông tin
A28: 25 | B28: CN_MOBILE Client3 | C28: Chức năng Client- phức tạp | D28: MOBILE | E28: > 10 trường thông tin - Component hiển thị thông tin: 1 đơn vị giao diện - Component nhập thông tin và xử lý thông tin: 2 đơn vị giao diện - Component phải gọi API riêng để lấy dữ liệu và xử lý dữ liệu: 3 đơn vị giao diện | F28: Trên giao diện của một chức năng có 1 Label, 2 textbox, 3 combobox (có gọi API để lấy dữ liệu) sẽ là: 1*1 + 2*2 + 3*3 = 12 trường thông tin
A29: 26 | B29: CN_MOBILE Server1 | C29: Chức năng Server- đơn giản | D29: MOBILE | E29: Nghiệp vụ nhỏ hơn 5 bước Bước là 1 xử lý logic được mô tả trong tài liệu giải pháp
A30: 27 | B30: CN_MOBILE Server2 | C30: Chức năng Server- trung bình | D30: MOBILE | E30: Nghiệp vụ từ 5 - 10 bước
A31: 28 | B31: CN_MOBILE Server3 | C31: Chức năng Server- phức tạp | D31: MOBILE | E31: Nghiệp vụ lớn hơn 10 bước
A32: 29 | B32: GD1_CUT | C32: Cắt nghiệp vụ đơn giản | D32: HTML, CSS, JS | E32: Cắt giao diện chức năng đơn giản, màn hình < 10 trường | F32: Màn hình chi tiết thông tin, màn hình tin tức
A33: 30 | B33: GD2_CUT | C33: Cắt nghiệp vụ phức tạp | D33: HTML, CSS, JS | E33: Cắt giao diện phức tạp, cắt full toàn màn hình (menu, banner, bottom..) | F33: Màn hình home MyViettel wap
A34: 31 | B34: CN_WEB1 | C34: Chức năng web bao gồm UI + Service - đơn giản | D34: UI - WEB | E34: Dưới 10 component Component : là những hiển thị ra; case validate
A35: 32 | B35: CN_WEB2 | C35: Chức năng web bao gồm UI + Service - trung bình | D35: UI - WEB | E35: Có 10-20 trường thông tin
A36: 33 | B36: CN_WEB3 | C36: Chức năng web bao gồm UI + Service - phức tạp | D36: UI - WEB | E36: Có hơn 20 trường thông tin
A37: 34 | B37: TT_DB1 | C37: Tiến trình đồng bộ dữ liệu các hệ thống đơn giản | D37: TT | E37: Nghiệp vụ bổ sung nhỏ hơn 5 bước
A38: 35 | B38: TT_DB2 | C38: Tiến trình đồng bộ dữ liệu các hệ thống trung bình | D38: TT | E38: Nghiệp vụ bổ sung từ 5 - 10 bước
A39: 36 | B39: TT_DB3 | C39: Tiến trình đồng bộ dữ liệu các hệ thống phức tạp | D39: TT | E39: Nghiệp vụ lớn hơn 10 bước
A40: 37 | B40: XML1 | C40: Xử lý text có cú pháp, như XML/JSON/YAML đơn giản | D40: XML | E40: Bản tin <10 trường thông tin
A41: 38 | B41: XML2 | C41: Xử lý text có cú pháp, như XML/JSON/YAML trung bình | D41: XML | E41: Bản tin từ 10 -20 trường thông tin
...

Sheet CSDL_CN
A1: PHỤ LỤC 1.3 CƠ SỞ DỮ LIỆU CHỨC NĂNG
A2: TT | B2: Loại chức năng | C2: Loại công việc | D2: Key (Tự sinh) | E2: Nỗ lực (MH)
A4: 1 | B4: NVJ1-PTM | C4: Giải pháp | D4: =B4&C4 | E4: 8
A5: 2 | B5: NVJ1-PTM | C5: Phát triển | D5: =B5&C5 | E5: 12
A6: 3 | B6: NVJ1-PTM | C6: Kiểm thử | D6: =B6&C6 | E6: 8
A7: 4 | B7: NVJ2-PTM | C7: Giải pháp | D7: =B7&C7 | E7: 10
A8: 5 | B8: NVJ2-PTM | C8: Phát triển | D8: =B8&C8 | E8: 20
A9: 6 | B9: NVJ2-PTM | C9: Kiểm thử | D9: =B9&C9 | E9: 14
A10: 7 | B10: NVJ3-PTM | C10: Giải pháp | D10: =B10&C10 | E10: 16
A11: 8 | B11: NVJ3-PTM | C11: Phát triển | D11: =B11&C11 | E11: 26
A12: 9 | B12: NVJ3-PTM | C12: Kiểm thử | D12: =B12&C12 | E12: 23
A13: 10 | B13: GD_WEB1 | C13: Giải pháp | D13: =B13&C13 | E13: 6
A14: 11 | B14: GD_WEB1 | C14: Phát triển | D14: =B14&C14 | E14: 12
A15: 12 | B15: GD_WEB1 | C15: Kiểm thử | D15: =B15&C15 | E15: 8
... A241: 238 | B241: RUN_MOBILE_IOS_2 | C241: Kiểm thử | D241: =B241&C241 | E241: 20
A242: 239 | B242: RUN_MOBILE_IOS_2 | C242: Giải pháp | D242: =B242&C242
A243: 240 | B243: RUN_MOBILE_IOS_2 | C243: Phát triển | D243: =B243&C243
A244: 241 | B244: RUN_MOBILE_IOS_3 | C244: Kiểm thử | D244: =B244&C244 | E244: 28
A245: 242 | B245: RUN_MOBILE_IOS_3 | C245: Giải pháp | D245: =B245&C245
A246: 243 | B246: RUN_MOBILE_IOS_3 | C246: Phát triển | D246: =B246&C246
A247: 244 | B247: CN_MOBILE Client1-NC | C247: Giải pháp | D247: =B247&C247 | E247: 2
A248: 245 | B248: CN_MOBILE Client1-NC | C248: Phát triển | D248: =B248&C248 | E248: 4
A249: 246 | B249: CN_MOBILE Client1-NC | C249: Kiểm thử | D249: =B249&C249 | E249: 4
A250: 247 | B250: CN_MOBILE Client2-NC | C250: Giải pháp | D250: =B250&C250 | E250: 4
A251: 248 | B251: CN_MOBILE Client2-NC | C251: Phát triển | D251: =B251&C251 | E251: 8.75
A252: 249 | B252: CN_MOBILE Client2-NC | C252: Kiểm thử | D252: =B252&C252 | E252: 10.5
A253: 250 | B253: CN_MOBILE Client3-NC | C253: Giải pháp | D253: =B253&C253 | E253: 7.5
A254: 251 | B254: CN_MOBILE Client3-NC | C254: Phát triển | D254: =B254&C254 | E254: 13
A255: 252 | B255: CN_MOBILE Client3-NC | C255: Kiểm thử | D255: =B255&C255 | E255: 18
A256: 253 | B256: CN_MOBILE Server1-NC | C256: Giải pháp | D256: =B256&C256 | E256: 2
A257: 254 | B257: CN_MOBILE Server1-NC | C257: Phát triển | D257: =B257&C257 | E257: 3.5
A258: 255 | B258: CN_MOBILE Server1-NC | C258: Kiểm thử | D258: =B258&C258 | E258: 4
... A264: 261 | B264: CN_MOBILE Server3-NC | C264: Kiểm thử | D264: =B264&C264 | E264: 18
A265: 262 | B265: UNITTEST | C265: Nỗ lực unit Test | D265: =B265&C265 | E265: Bằng 30% nỗ lực lập trình

Sheet CSDL Phi CN
A1: PHỤ LỤC 1.4 CƠ SỞ DỮ LIỆU PHI CHỨC NĂNG
A3: STT | B3: Mã đầu việc | C3: Đầu việc | D3: Phạm vi | E3: Ví dụ | F3: Mô tả công việc | G3: Nỗ lực thực hiện (MH)
A4: 1 | B4: QTDA | C4: Nỗ lực QTDA | D4: Hệ thống | G4: 10% nỗ lực
A5: 2 | B5: QA | C5: Nỗ lực QA dự án | D5: Hệ thống | G5: 0.03
A6: 3 | B6: TH | C6: Test Tích hợp hệ thống khác | D6: Hê thống | G6: 12
A7: 4 | B7: NT1 | C7: Nghiệm thu nội bộ | D7: Hệ thống | G7: 5
A8: 5 | B8: NT2 | C8: Nghiệm thu khách hàng | D8: Hệ thống | G8: 3.1090909
A9: 6 | B9: SZ1 | C9: Sizing có hệ thống tham chiếu có sẵn | D9: Tham chiếu theo số module (jvm chạy) 1 - 5 module | G9: 8
A10: 7 | B10: SZ2 | C10: Sizing có hệ thống tham chiếu có sẵn | D10: Tham chiếu theo số module (jvm chạy): 6-10 module | G10: 16
A11: 8 | B11: SZ3 | C11: Sizing có hệ thống tham chiếu có sẵn | D11: Tham chiếu theo số module (jvm chạy): >10 module | G11: 80
A12: 9 | B12: SZ4 | C12: Sizing tự test đo trên lab | D12: Tham chiếu theo số module (jvm chạy) 1 - 5 module | G12: 4
A13: 10 | B13: SZ5 | C13: Sizing tự test đo trên lab | D13: Tham chiếu theo số module (jvm chạy): 6-10 module | G13: 8
A14: 11 | B14: SZ6 | C14: Sizing tự test đo trên lab | D14: Tham chiếu theo số module (jvm chạy): >10 module | G14: 12
A15: 12 | B15: UC1 | C15: Làm các thủ tục upcode và bàn giao trên WO | G15: 2
A16: 13 | B16: UC2 | C16: Review và phê duyệt WO upcode | G16: 2.1490683
A17: 14 | B17: UC3 | C17: Merge code | E17: 5% nỗ lực coding các chức năng merge | G17: 3.6790123
A18: 15 | B18: UC4 | C18: Test Merge code | E18: 20% tổng nỗ lực test các yc merge | G18: 10
A19: 16 | B19: UC5 | C19: Tham gia upcode | G19: 3.3838509
A20: 17 | B20: UC6 | C20: Release phiên bản trên jenskin và Cập nhật kết quả upcode trên IBM | G20: 2.8054054
A21: 18 | B21: TK1 | C21: Triển khai trên hạ tầng có sẵn | G21: 6.05
A22: 19 | B22: TK2 | C22: Triển khai mở rộng trên hạ tầng có sẵn | D22: Bổ sung 1 -5 server | G22: 6.1333333
A23: 20 | B23: TK3 | C23: Triển khai mở rộng trên hạ tầng có sẵn | D23: Bổ sung 6-10 server | G23: 9.1310345
A24: 21 | B24: TK4 | C24: Triển khai hệ thống mới trên hạ tầng mới | D24: Bổ sung 1 -5 server | G24: 6.4
A25: 22 | B25: TK5 | C25: Triển khai hệ thống mới trên hạ tầng mới | D25: Bổ sung 6-10 server | G25: 7.2
A26: 23 | B26: TK6 | C26: Triển khai hệ thống mới trên hạ tầng mới | D26: Bổ sung > 10 server | G26: 83.84
A27: 24 | B27: TK7 | C27: Hồ sơ kỹ thuật | G27: 72
A28: 25 | B28: TK8 | C28: Bộ chỉ tiêu kỹ thuật | G28: 7.2
A29: 26 | B29: TK9 | C29: Dựng môi trường test hiệu năng | G29: 5.6
A30: 27 | B30: TK10 | C30: Test hiệu năng | G30: 12
A31: 28 | B31: TK11 | C31: Báo cáo và đánh giá hệ thống sau test hiệu năng | G31: 7.2
A32: 29 | B32: DT1 | C32: Đào tạo VHKT | G32: 2
A33: 30 | B33: DT2 | C33: Đào tạo Người dùng | G33: 2
A34: 31 | B34: DT3 | C34: Đào tạo CSKH | G34: 2
A35: 32 | B35: DT4 | C35: Tài liệu HDVH | G35: 4
A36: 33 | B36: DT5 | C36: Tài liệu HDKT | G36: 2
A37: 34 | B37: DT6 | C37: Tài liệu hướng dẫn cài đặt | G37: 4
A38: 35 | B38: VH1 | C38: Rà soát ATTT server | G38: 4
... A41: 38 | B41: VH4 | C41: Khai báo cảnh báo, giám sát | G41: 28
A42: 39 | B42: VH5 | C42: Hỗ trợ phản ánh | D42: - Hệ thống đã bàn giao | G42: 1.8823529
A43: 40 | B43: VH6 | C43: Hỗ trợ phản ánh | D43: - Hệ thống chưa bàn giao: | G43: 24
...
